<?xml version="1.0"?>
<robot name="arm">

    <link name="base_link">
        <visual>
            <geometry>
                <box size="0.5 0.5 0.1"/>
            </geometry>
            <origin xyz="0 0 0" rpy="0 0 0"/>
            <material name="gray">
                <color rgba="0.5 0.5 0.5 1"/>
            </material>
        </visual>
    </link>

    <link name="link1">
        <visual>
            <geometry>
                <cylinder radius="0.05" length="0.5"/>
            </geometry>
            <origin xyz="0 0 0.25" rpy="0 0 0"/>
            <material name="blue">
                <color rgba="0.0 0.0 1.0 1"/>
            </material>
        </visual>
    </link>

    <joint name="joint1" type="revolute">
        <parent link = "base_link"/>
        <child link = "link1"/>
        <origin xyz="0 0 0" rpy="0 0 0"/>
        <axis xyz="0 0 1"/>
        <limit lower="-3.14" upper="3.14" effort="1.0" velocity="1.0" />
    </joint>

    <link name = "link2">
        <visual>
            <geometry>
                <cylinder radius = "0.05" length = "0.5"/>
            </geometry>
            <origin xyz = "0 0 0.25" rpy = "0 0 0"/>
            <material name = "red">
                <color rgba="1.0 0.0 0.0 1"/>
            </material>
        </visual>
    </link>

    <joint name = "joint2" type = "revolute">
        <parent link = "link1"/>
        <child link = "link2"/>
        <origin xyz = "1.0 0 0" rpy = "0 0 0"/>
        <axis xyz = "0 0 1"/>
        <limit lower = "-3.14" upper = "3.14" effort = "1.0" velocity = "1.0"/>
    </joint>

</robot>