<?xml version="1.0"?>
<robot name="arm">

    <link name = "world"/>
    <link name="base_link">
        <inertial>
            <origin xyz = "0 0 0.05" rpy= "0 0 0"/>
            <mass value = "1.0"/>
            <inertia ixx="0.01" ixy="0.0" ixz="0.0" iyy="0.01"  iyz="0.0"
             izz="0.01"/>
        </inertial>
        <visual>
            <origin xyz ="0 0 0.05" rpy = "0 0 0"/>
            <geometry>
                <box size="0.5 0.5 0.1"/>
            </geometry>
            <!-- <origin xyz="0 0 0" rpy="0 0 0"/> -->
            <material name="gray">
                <color rgba="0.5 0.5 0.5 1"/>
            </material>
        </visual>
        <collision>
            <origin xyz="0 0 0.05" rpy="0 0 0"/>
            <geometry>
                <box size="0.5 0.5 0.1"/>
            </geometry>
        </collision>
    </link>
    <joint name="camera_joint" type="fixed">
        <parent link="base_link"/>
        <child link="camera_link"/>
        <origin xyz="0.1 0.1 0.1" rpy="0 0 0"/>
    </joint>

    <link name="camera_link">
        <visual>
            <geometry>
                <box size="0.05 0.1 0.1"/>
            </geometry>
        </visual>
    </link>

    <!-- <joint name="camera_optical_joint" type="fixed">
        <parent link="camera_link"/>
        <child link="camera_optical_frame"/>
        <origin xyz="0 0 0" rpy="-1.57 0 -1.57"/>
    </joint>

    <link name="camera_optical_frame"/> -->
        
    <gazebo reference="camera_link">
        <material>Gazebo/Black</material>
        
        <sensor name="camera" type="camera">
            <pose>0.1 0.1 0.1 0 0 0</pose>
            <always_on>true</always_on>
            <update_rate>30</update_rate>
            <visualize>true</visualize>
            <topic>camera/image_raw</topic>
            <gz_frame_id>camera_link_optical</gz_frame_id>
            <camera>
                <camera_info_topic>camera/camera_info</camera_info_topic>
                <horizontal_fov>2.0</horizontal_fov>
                <image>
                    <width>640</width>
                    <height>480</height>
                    <format>R8G8B8</format>
                </image>
                <clip>
                    <near>0.1</near>
                    <far>100</far>
                </clip>
            </camera>
            
        </sensor>
    </gazebo>

    <joint name="world_joint" type="fixed">
        <parent link="world"/>
        <child link="base_link"/>
        <origin xyz="0 0 0" rpy="0 0 0"/>
    </joint>

    <!-- <link name = "world"/> -->

    <link name="link1">
        <inertial>
            <origin xyz = "0 0 0.25" rpy= "0 0 0"/>
            <mass value = "1.0"/>
            <inertia ixx="0.021" ixy="0.0" ixz="0.0" iyy="0.021"  iyz="0.0" izz="0.01"/>
        </inertial>
        <visual>
            <origin xyz="0 0 0.25" rpy="0 0 0"/>
            <!-- <origin xyz="0 0 0.25" rpy="0 0 0"/> -->
            <geometry>
                <cylinder radius="0.05" length="0.5"/>
            </geometry>
            <material name="blue">
                <color rgba="0.0 0.0 1.0 1"/>
            </material>
        </visual>
        <collision>
            <origin xyz="0 0 0.25" rpy="0 0 0"/>
            <geometry>
                <cylinder radius="0.05" length="0.5"/>
            </geometry>
        </collision>
    </link>

    <joint name="joint1" type="revolute">
        <parent link = "base_link"/>
        <child link = "link1"/>
        <origin xyz="0 0 0.1" rpy="0 0 0"/>
        <axis xyz="0 0 1"/>
        <limit lower="-3.14" upper="3.14" effort="100.0" velocity="1.0" />
        <dynamics damping="0.5" friction="0.1"/>
    </joint>

    <link name = "link2">
        <inertial>
            <origin xyz = "0 0 0.25" rpy= "0 0 0"/>
            <mass value = "1.0"/>
            <inertia ixx="0.01" ixy="0.0" ixz="0.0" iyy="0.01"  iyz="0.0" izz="0.01"/>
        </inertial>
        <visual>
            <origin xyz = "0 0 0.25" rpy = "0 0 0"/>
            <geometry>
                <cylinder radius = "0.05" length = "0.5"/>
            </geometry>
            <material name = "red">
                <color rgba="1.0 0.0 0.0 1"/>
            </material>
        </visual>
        <collision>
            <origin xyz="0 0 0.25" rpy="0 0 0"/>
            <geometry>
                <cylinder radius = "0.05" length = "0.5"/>
            </geometry>
        </collision>
    </link>

    <joint name = "joint2" type = "revolute">
        <parent link = "link1"/>
        <child link = "link2"/>
        <origin xyz = "0 0 0.5" rpy = "0 0 0"/>
        <axis xyz = "1 0 0"/>
        <limit lower = "-3.14" upper = "3.14" effort = "100.0" velocity = "1.0"/>
        <dynamics damping="0.5" friction="0.1"/>
    </joint>

            
   <ros2_control name="GazeboSimSystem" type="system">
        <hardware>
            <plugin>gz_ros2_control/GazeboSimSystem</plugin>
        </hardware>
        <joint name="joint1">
            <command_interface name="position"/>
            <state_interface name="position"/>
            <state_interface name="velocity"/>
        </joint>
        <joint name="joint2">
            <command_interface name="position"/>
            <state_interface name="position"/>
            <state_interface name="velocity"/>
        </joint>
    </ros2_control>

    <gazebo>
        <plugin filename="libgz_ros2_control-system.so" name="gz_ros2_control::GazeboSimROS2ControlPlugin">
            <robot_param>robot_description</robot_param>
            <robot_param_node>robot_state_publisher</robot_param_node>
            <parameters>/home/chintan/ros2_ws/install/my_robot_arm/share/my_robot_arm/config/pidcontroller.yaml</parameters>
            <controller_manager_name>controller_manager</controller_manager_name>
        </plugin>
    </gazebo>

</robot>