<?xml version="1.0"?>
<robot name="arm">

    <link name = "world"/>
    <link name="base_link">
        <inertial>
            <origin xyz = "0 0 0.05" rpy= "0 0 0"/>
            <mass value = "1.0"/>
            <inertia ixx="0.01" ixy="0.0" ixz="0.0" iyy="0.01"  iyz="0.0"
             izz="0.01"/>
        </inertial>
        <visual>
            <origin xyz ="0 0 0.05" rpy = "0 0 0"/>
            <geometry>
                <box size="0.5 0.5 0.1"/>
            </geometry>
            <!-- <origin xyz="0 0 0" rpy="0 0 0"/> -->
            <material name="gray">
                <color rgba="0.5 0.5 0.5 1"/>
            </material>
        </visual>
        <collision>
            <origin xyz="0 0 0.05" rpy="0 0 0"/>
            <geometry>
                <box size="0.5 0.5 0.1"/>
            </geometry>
        </collision>
    </link>

    <joint name="world_joint" type="fixed">
        <parent link="world"/>
        <child link="base_link"/>
        <origin xyz="0 0 0" rpy="0 0 0"/>
    </joint>

    <!-- <link name = "world"/> -->

    <link name="link1">
        <inertial>
            <origin xyz = "0 0 0.25" rpy= "0 0 0"/>
            <mass value = "1.0"/>
            <inertia ixx="0.021" ixy="0.0" ixz="0.0" iyy="0.021"  iyz="0.0" izz="0.01"/>
        </inertial>
        <visual>
            <origin xyz="0 0 0.25" rpy="0 0 0"/>
            <!-- <origin xyz="0 0 0.25" rpy="0 0 0"/> -->
            <geometry>
                <cylinder radius="0.05" length="0.5"/>
            </geometry>
            <material name="blue">
                <color rgba="0.0 0.0 1.0 1"/>
            </material>
        </visual>
        <collision>
            <origin xyz="0 0 0.25" rpy="0 0 0"/>
            <geometry>
                <cylinder radius="0.05" length="0.5"/>
            </geometry>
        </collision>
    </link>

    <joint name="joint1" type="revolute">
        <parent link = "base_link"/>
        <child link = "link1"/>
        <origin xyz="0 0 0.1" rpy="0 0 0"/>
        <axis xyz="0 0 1"/>
        <limit lower="-3.14" upper="3.14" effort="100.0" velocity="1.0" />
        <dynamics damping="0.5" friction="0.1"/>
    </joint>

    <link name = "link2">
        <inertial>
            <origin xyz = "0 0 0.25" rpy= "0 0 0"/>
            <mass value = "1.0"/>
            <inertia ixx="0.01" ixy="0.0" ixz="0.0" iyy="0.01"  iyz="0.0" izz="0.01"/>
        </inertial>
        <visual>
            <origin xyz = "0 0 0.25" rpy = "0 0 0"/>
            <geometry>
                <cylinder radius = "0.05" length = "0.5"/>
            </geometry>
            <material name = "red">
                <color rgba="1.0 0.0 0.0 1"/>
            </material>
        </visual>
        <collision>
            <origin xyz="0 0 0.25" rpy="0 0 0"/>
            <geometry>
                <cylinder radius = "0.05" length = "0.5"/>
            </geometry>
        </collision>
    </link>

    <joint name = "joint2" type = "revolute">
        <parent link = "link1"/>
        <child link = "link2"/>
        <origin xyz = "0 0 0.5" rpy = "0 0 0"/>
        <axis xyz = "1 0 0"/>
        <limit lower = "-3.14" upper = "3.14" effort = "100.0" velocity = "1.0"/>
        <dynamics damping="0.5" friction="0.1"/>
    </joint>

</robot>